<?xml version="1.0"?>
<robot xmlns:xacro="http://www.ros.org/wiki/xacro">
  <xacro:property name="chassis_length" value="0.2"/>
  <xacro:property name="chassis_width" value="0.15"/>
  <xacro:property name="chassis_height" value="0.05"/>
  <xacro:property name="wheel_radius" value="0.033"/>
  <xacro:property name="wheel_width" value="0.018"/>
  <xacro:property name="wheel_ygap" value="0.01"/>
  <xacro:property name="wheel_zoff" value="0.0"/>
  <xacro:property name="wheel_xoff" value="0.08"/>
  <xacro:property name="caster_xoff" value="0.06"/>
  <xacro:property name="chassis_mass" value="0.5"/>
  <xacro:property name="wheel_mass" value="0.1"/>
  <xacro:property name="caster_mass" value="0.05"/>

  <material name="white"><color rgba="1 1 1 1"/></material>
  <material name="black"><color rgba="0 0 0 1"/></material>
  <material name="blue"><color rgba="0 0 1 1"/></material>
  <material name="red"><color rgba="1 0 0 1"/></material>
  <material name="green"><color rgba="0 1 0 1"/></material>
  <material name="gray"><color rgba="0.5 0.5 0.5 1"/></material>

  <link name="base_footprint"/>

  <joint name="base_joint" type="fixed">
    <parent link="base_footprint"/>
    <child link="base_link"/>
    <origin xyz="0 0 ${wheel_radius}" rpy="0 0 0"/>
  </joint>

  <link name="base_link">
    <visual>
      <origin xyz="0 0 ${chassis_height/2}"/>
      <geometry><box size="${chassis_length} ${chassis_width} ${chassis_height}"/></geometry>
      <material name="white"/>
    </visual>
    <collision>
      <origin xyz="0 0 ${chassis_height/2}"/>
      <geometry><box size="${chassis_length} ${chassis_width} ${chassis_height}"/></geometry>
    </collision>
    <inertial>
      <origin xyz="0 0 ${chassis_height/2}"/>
      <mass value="${chassis_mass}"/>
      <inertia ixx="${chassis_mass*(chassis_width**2 + chassis_height**2)/12}" ixy="0" ixz="0"
               iyy="${chassis_mass*(chassis_length**2 + chassis_height**2)/12}" iyz="0"
               izz="${chassis_mass*(chassis_length**2 + chassis_width**2)/12}"/>
    </inertial>
  </link>

  <!-- VISIBLE ARUCO MARKER ON FRONT -->
  <link name="aruco_marker_link">
    <visual>
      <origin xyz="0 0 0" rpy="0 0 0"/>
      <geometry><box size="0.001 0.05 0.05"/></geometry>
      <material name="aruco_mat_${bot_marker_id}">
        <script>
          <uri>package://dna_swarm_bot/description/materials/scripts</uri>
          <uri>package://dna_swarm_bot/description/textures</uri>
          <name>ArucoMarker/Bot${bot_marker_id}</name>
        </script>
      </material>
    </visual>
    <collision>
      <origin xyz="0 0 0"/>
      <geometry><box size="0.001 0.05 0.05"/></geometry>
    </collision>
  </link>

  <joint name="aruco_marker_joint" type="fixed">
    <parent link="base_link"/>
    <child link="aruco_marker_link"/>
    <origin xyz="${chassis_length/2 + 0.001} 0 ${chassis_height/2}" rpy="0 0 0"/>
  </joint>

  <xacro:macro name="wheel" params="prefix x_reflect y_reflect">
    <link name="${prefix}_wheel">
      <visual>
        <origin xyz="0 0 0" rpy="${pi/2} 0 0"/>
        <geometry><cylinder radius="${wheel_radius}" length="${wheel_width}"/></geometry>
        <material name="black"/>
      </visual>
      <collision>
        <origin xyz="0 0 0" rpy="${pi/2} 0 0"/>
        <geometry><cylinder radius="${wheel_radius}" length="${wheel_width}"/></geometry>
      </collision>
      <inertial>
        <origin xyz="0 0 0" rpy="${pi/2} 0 0"/>
        <mass value="${wheel_mass}"/>
        <inertia ixx="${wheel_mass*(3*wheel_radius**2 + wheel_width**2)/12}" ixy="0" ixz="0"
                 iyy="${wheel_mass*(3*wheel_radius**2 + wheel_width**2)/12}" iyz="0"
                 izz="${wheel_mass*wheel_radius**2/2}"/>
      </inertial>
    </link>
    <joint name="${prefix}_wheel_joint" type="continuous">
      <parent link="base_link"/>
      <child link="${prefix}_wheel"/>
      <origin xyz="${x_reflect*wheel_xoff} ${y_reflect*(chassis_width/2+wheel_ygap)} ${wheel_zoff}" rpy="0 0 0"/>
      <axis xyz="0 1 0"/>
    </joint>
  </xacro:macro>

  <xacro:wheel prefix="left" x_reflect="-1" y_reflect="1"/>
  <xacro:wheel prefix="right" x_reflect="-1" y_reflect="-1"/>

  <link name="caster_wheel">
    <visual><geometry><sphere radius="0.02"/></geometry><material name="black"/></visual>
    <collision><geometry><sphere radius="0.02"/></geometry></collision>
    <inertial>
      <mass value="${caster_mass}"/>
      <inertia ixx="${2*caster_mass*0.02**2/5}" ixy="0" ixz="0"
               iyy="${2*caster_mass*0.02**2/5}" iyz="0"
               izz="${2*caster_mass*0.02**2/5}"/>
    </inertial>
  </link>
  <joint name="caster_wheel_joint" type="fixed">
    <parent link="base_link"/>
    <child link="caster_wheel"/>
    <origin xyz="${caster_xoff} 0 ${-wheel_radius+0.02}" rpy="0 0 0"/>
  </joint>

  <link name="imu_link">
    <visual><geometry><box size="0.02 0.02 0.01"/></geometry><material name="blue"/></visual>
  </link>
  <joint name="imu_joint" type="fixed">
    <parent link="base_link"/>
    <child link="imu_link"/>
    <origin xyz="0 0 ${chassis_height+0.005}" rpy="0 0 0"/>
  </joint>

  <link name="face_link">
    <visual><geometry><box size="0.01 0.05 0.03"/></geometry><material name="red"/></visual>
  </link>
  <joint name="face_joint" type="fixed">
    <parent link="base_link"/>
    <child link="face_link"/>
    <origin xyz="${chassis_length/2+0.005} 0 ${chassis_height/2}" rpy="0 0 0"/>
  </joint>
</robot>
